test_end_to_end_destibrom.py::DestiBromTesting::test_add_sponsored_and_ads
--------------------------------------------------------------------
Last Page: https://v1-destibrom-staging.itdev.app/sponsored-ads
 Duration: 3.09s
  Browser: Chrome 119.0.6045.200
   Driver: chromedriver 119.0.6045.105
Timestamp: 1701703880  (Unix Timestamp)
     Date: Monday, 4 December 2023
     Time: 11:31:20 PM  (Malay Peninsula Standard Time, UTC+08:00)
--------------------------------------------------------------------
Traceback:
  File "C:\SeleniumPython\tests_destibrom\test_end_to_end_destibrom.py", line 39, in test_add_sponsored_and_ads
    self.add_new_for_sponsored_ads()
  File "C:\SeleniumPython\pages_destibrom\sponsored_ads_page.py", line 30, in add_new_for_sponsored_ads
    website_url = website_generator.generate_random_website()
                  ^^^^^^^^^^^^^^^^^^^^^^^^^^^^^^^^^^^^^^^^^^^
  File "C:\SeleniumPython\utilities\random_website_generator.py", line 20, in generate_random_website
    return self.generate_random_website()
           ^^^^^^^^^^^^^^^^^^^^^^^^^^^^^^
  File "C:\SeleniumPython\utilities\random_website_generator.py", line 15, in generate_random_website
    response = requests.get(website_url)
               ^^^^^^^^^^^^^^^^^^^^^^^^^
  File "C:\SeleniumPython\venv\Lib\site-packages\requests\api.py", line 73, in get
    return request("get", url, params=params, **kwargs)
           ^^^^^^^^^^^^^^^^^^^^^^^^^^^^^^^^^^^^^^^^^^^^
  File "C:\SeleniumPython\venv\Lib\site-packages\requests\api.py", line 59, in request
    return session.request(method=method, url=url, **kwargs)
           ^^^^^^^^^^^^^^^^^^^^^^^^^^^^^^^^^^^^^^^^^^^^^^^^^
  File "C:\SeleniumPython\venv\Lib\site-packages\requests\sessions.py", line 589, in request
    resp = self.send(prep, **send_kwargs)
           ^^^^^^^^^^^^^^^^^^^^^^^^^^^^^^
  File "C:\SeleniumPython\venv\Lib\site-packages\requests\sessions.py", line 703, in send
    r = adapter.send(request, **kwargs)
        ^^^^^^^^^^^^^^^^^^^^^^^^^^^^^^^
  File "C:\SeleniumPython\venv\Lib\site-packages\requests\adapters.py", line 519, in send
    raise ConnectionError(e, request=request)
Exception: HTTPSConnectionPool(host='donosworlds.gg', port=443): Max retries exceeded with url: /contact (Caused by NameResolutionError("<urllib3.connection.HTTPSConnection object at 0x000001B31BD5F290>: Failed to resolve 'donosworlds.gg' ([Errno 11001] getaddrinfo failed)"))